Start Training
No checkpoint found, using pre-trained model.
Traceback (most recent call last):
  File "/home/jl5824/pfs-neural-net/train.py", line 159, in <module>
    gnn.load_state_dict(torch.load('model_gnn' + ID + '.pth'))
                        ^^^^^^^^^^^^^^^^^^^^^^^^^^^^^^^^^^^^^
  File "/home/jl5824/.conda/envs/torch-gnn/lib/python3.12/site-packages/torch/serialization.py", line 1479, in load
    with _open_file_like(f, "rb") as opened_file:
         ^^^^^^^^^^^^^^^^^^^^^^^^
  File "/home/jl5824/.conda/envs/torch-gnn/lib/python3.12/site-packages/torch/serialization.py", line 759, in _open_file_like
    return _open_file(name_or_buffer, mode)
           ^^^^^^^^^^^^^^^^^^^^^^^^^^^^^^^^
  File "/home/jl5824/.conda/envs/torch-gnn/lib/python3.12/site-packages/torch/serialization.py", line 740, in __init__
    super().__init__(open(name, mode))
                     ^^^^^^^^^^^^^^^^
FileNotFoundError: [Errno 2] No such file or directory: 'model_gnn0.pth'

During handling of the above exception, another exception occurred:

Traceback (most recent call last):
  File "/home/jl5824/pfs-neural-net/train.py", line 162, in <module>
    gnn.load_state_dict(torch.load('model_gnn_pre' + ID + '.pth'))
                        ^^^^^^^^^^^^^^^^^^^^^^^^^^^^^^^^^^^^^^^^^
  File "/home/jl5824/.conda/envs/torch-gnn/lib/python3.12/site-packages/torch/serialization.py", line 1479, in load
    with _open_file_like(f, "rb") as opened_file:
         ^^^^^^^^^^^^^^^^^^^^^^^^
  File "/home/jl5824/.conda/envs/torch-gnn/lib/python3.12/site-packages/torch/serialization.py", line 759, in _open_file_like
    return _open_file(name_or_buffer, mode)
           ^^^^^^^^^^^^^^^^^^^^^^^^^^^^^^^^
  File "/home/jl5824/.conda/envs/torch-gnn/lib/python3.12/site-packages/torch/serialization.py", line 740, in __init__
    super().__init__(open(name, mode))
                     ^^^^^^^^^^^^^^^^
FileNotFoundError: [Errno 2] No such file or directory: 'model_gnn_pre0.pth'
